Workbook
Name IQ_CH: 110000
Name IQ_CQ: 5000
Name IQ_CY: 10000
Name IQ_DAILY: 500000
Name IQ_FH: 100000
Name IQ_FQ: 500
Name IQ_FY: 1000
Name IQ_LTM: 2000
Name IQ_MONTH: 15000
Name IQ_NTM: 6000
Name IQ_WEEK: 50000
Name IQ_YTD: 3000

Sheet Input Sheet
B3: Please Provide the below Inputs
B5: Name of the Company | C5: Marico Ltd
B7: WACC Inputs
B8: Country | C8: India
B9: Local Currency 10Y Government Yield | C9: 0.0651
B10: =C8&"'s"&" Moodys Sovereign Rating" -> India's Moodys Sovereign Rating | C10: =VLOOKUP(C8,'Damodaran Data'!B4:D161,3,FALSE) -> Baa3
B11: Credit Default spread as per Dr Damodaran | C11: =VLOOKUP(C8,'Damodaran Data'!B4:E161,4,) -> 0.021609858
B12: Implied US Equity Risk Premium | C12: 0.0373
B13: Asset Beta | C13: 0.45
B14: Asset Beta Variation (+/-) | C14: 0.05
B15: Debt to Equity Ratio | C15: ='Assumptions Working '!I659 -> 0.095345912
B16: Debt to Capital (Gearing) | C16: ='Assumptions Working '!I660 -> 0.081593111 | Z16: Large | AB16: Yes
B17: Marginal Tax Rate | C17: 0.2512 | Z17: Small | AB17: No
B18: Company Credit Rating Available? | C18: Yes
B19: Company is Large Firm or Small Firm | C19: Large
B20: Provide Credit Rating | C20: Aaa/AAA
B21: Interest Coverage Ratio | C21: ='3 Statement Model'!N47 -> 50.047842
B22: ICR Based Corporate Default Spread | C22: =IF(C19="Largr",VLOOKUP(C21,'Damodaran Data'!G6:J21,4,TRUE),VLOOKUP('Input Sheet'!C21,'Damodaran Data'!L6:O21,4,TRUE)) -> 0.0045
B23: Small Size Premium | C23: 0.026

Sheet WACC
B2: ='Input Sheet'!C5 -> Marico Ltd
B3: Weighted Average Cost of Capital
B5: Particulars | D5: Low | E5: Mid | F5: High | H5: Risk Free Rate
B7: Risk Free Rate | D7: ='Input Sheet'!C9-'Input Sheet'!C11 -> 0.043490142 | E7: =D7 -> 0.043490142 | F7: =E7 -> 0.043490142 | H7: ="We have considered "&TEXT(E7,"0.00%")&" as the risk free rate in estimation of cost of equity of "&TEXT(E12,"0.00%")&". The risk free rate of India is calculated by considering local currency 10 years government bond yield adjusted for default spread of India." -> We have considered 4.35% as the risk free rate in estimation of cost of equity of 7.19%. The risk free rate of India is calculated by considering local currency 10 years government bond yield adjusted for default spread of India.
B8: Equity Risk Premium | D8: ='Input Sheet'!C12+'Input Sheet'!C11 -> 0.058909858 | E8: =D8 -> 0.058909858 | F8: =E8 -> 0.058909858
B9: Asset Beta | D9: =E9-'Input Sheet'!C14 -> 0.4 | E9: ='Input Sheet'!C13 -> 0.45 | F9: =E9+'Input Sheet'!C14 -> 0.5
B10: D/E Ratio | D10: ='Input Sheet'!C15 -> 0.095345912 | E10: =D10 -> 0.095345912 | F10: =E10 -> 0.095345912
B11: Equity Beta | D11: =D9*(1+(D10*(1-'Input Sheet'!$C$17))) -> 0.42855801 | E11: =E9*(1+(E10*(1-'Input Sheet'!$C$17))) -> 0.48212776 | F11: =F9*(1+(F10*(1-'Input Sheet'!$C$17))) -> 0.53569751
B12: CAMP Cost of Equity | D12: =D7+(D8*D11) -> 0.068736433 | E12: =E7+(E8*E11) -> 0.07189222 | F12: =F7+(F8*F11) -> 0.075048006 | H12: Asset Beta
H13: ="We have estimated an asset beta range of "&TEXT(D9,"0.00")&" to "&TEXT(F9,"0.00")&", with a mid point of "&TEXT(E9,"0.00")&" based on observed median of 5 year monthly asset beta of benchmark listed companies adjusted for blume effect." -> We have estimated an asset beta range of 0.40 to 0.50, with a mid point of 0.45 based on observed median of 5 year monthly asset beta of benchmark listed companies adjusted for blume effect.
B14: Small Size Premium | D14: ='Input Sheet'!C23 -> 0.026 | E14: =D14 -> 0.026 | F14: =E14 -> 0.026
B15: Asset Specific Premium | D15: 0 | E15: =D15 -> 0 | F15: =E15 -> 0
B16: Modified Cost of Equity | D16: =D12+D14+D15 -> 0.094736433 | E16: =E12+E14+E15 -> 0.09789222 | F16: =F12+F14+F15 -> 0.10104801
H17: Equity Risk Premium (ERP)
B18: Pre Tax Cost of Debt | D18: ='Input Sheet'!C9+(IF('Input Sheet'!C18="No",'Input Sheet'!C22,VLOOKUP('Input Sheet'!C20,'Damodaran Data'!I7:J21,2,FALSE))) -> 0.0696 | E18: =D18 -> 0.0696 | F18: =E18 -> 0.0696 | H18: ="An ERP of "&TEXT(E8,"0.00%") &" has been adopted based on US implied equity risk premium, relative equity volatiliy of ICE BofA Public Sector Issues Emerging Mkts Index, S&P Emerging BMI Index and country risk premium of India." -> An ERP of 5.89% has been adopted based on US implied equity risk premium, relative equity volatiliy of ICE BofA Public Sector Issues Emerging Mkts Index, S&P Emerging BMI Index and country risk premium of India.
B19: Marginal Tax Rate | D19: ='Input Sheet'!C17 -> 0.2512 | E19: =D19 -> 0.2512 | F19: =E19 -> 0.2512
B20: Post Tax Cost of Debt | D20: =D18*(1-D19) -> 0.05211648 | E20: =E18*(1-E19) -> 0.05211648 | F20: =F18*(1-F19) -> 0.05211648
B22: Capital Gearing (D/D+E) | D22: ='Input Sheet'!C16 -> 0.081593111 | E22: =D22 -> 0.081593111 | F22: =E22 -> 0.081593111 | H22: Cost of Debt
B23: Weighted Average Cost of Capital | D23: =(D20*D22)+(D16*(1-D22)) -> 0.091258939 | E23: =(E20*E22)+(E16*(1-E22)) -> 0.094157235 | F23: =(F20*F22)+(F16*(1-F22)) -> 0.097055531 | H23: For the purpose of assessing the cost of debt, we have used country's risk free rate, country's default spread and corporate default spread based on company's debt rating and interest coverage ratio
B24: Weighted Average Cost of Capital (Rounded) | D24: =ROUNDUP(D23,2) -> 0.1 | E24: =ROUNDUP(E23,2) -> 0.1 | F24: =ROUNDUP(F23,2) -> 0.1
B26: 1. Tax rate is considered as Marginal Tax Rate of India
B27: 2. Asset Beta is considered as median of 5 years beta of comps adjusted for blume afeect
B28: 3. Equity Beta = Asset Beta * (1+(1-Tax Rate%)*(Debt/Equity) | H28: Small Size Premium & Asset Specific Premium
H29: Emperically small size assets have exceeded the returns as compared to large sized asset. We have used the study on size premium conducted by Incwert which is based on difference between actual return and CAPM expected returns arranged in decile basis market capitalization of Indian companies.
B40: =B2 -> Marico Ltd
B41: Beta Analysis - 2 Years Weekly
B44: Comparable Company | D44: Ticker | E44: No.of Weekly Observations | F44: Market Cap (Cr) | G44: Asset Beta | H44: 2 Years avg D/E | I44: Equity Beta | J44: 2 Years avg D/D+E | L44: Considered ?
B46: Dabur India | D46: NSE: DABUR | E46: 104 | F46: 91,904 | G46: =I46/(1+(H46*(1-'Input Sheet'!$C$17))) -> 0.61445013 | H46: ='Cal Sheet'!C53 -> 0.092479565 | I46: 0.657 | J46: ='Cal Sheet'!E53 -> 0.084175573 | L46: Yes
B47: Hindustan Unilever | D47: NSE: HINDUNILVR | E47: 104 | F47: 569870 | G47: =I47/(1+(H47*(1-'Input Sheet'!$C$17))) -> 0.38796019 | H47: ='Cal Sheet'!C54 -> 0.00013702956 | I47: 0.388 | J47: ='Cal Sheet'!E54 -> 0.00013699715 | L47: Yes
B48: Sundrop Brands Ltd | D48: NSE: SUNDROP | E48: 104 | F48: 2857 | G48: =I48/(1+(H48*(1-'Input Sheet'!$C$17))) -> 0.44874336 | H48: ='Cal Sheet'!C55 -> 0.0335 | I48: 0.46 | J48: ='Cal Sheet'!E55 -> 0.031396439 | L48: No
B49: Gokul Agro Resources Ltd | D49: NSE: GOKULAGRO | E49: 104 | F49: 6071 | G49: =I49/(1+(H49*(1-'Input Sheet'!$C$17))) -> 0.87049777 | H49: ='Cal Sheet'!C56 -> 0.62823592 | I49: 1.28 | J49: ='Cal Sheet'!E56 -> 0.38256343 | L49: No
B50: Godrej Consumer Products Ltd | D50: NSE: GODREJCP | E50: 104 | F50: 118072 | G50: =I50/(1+(H50*(1-'Input Sheet'!$C$17))) -> 0.43543924 | H50: ='Cal Sheet'!C57 -> 0.2869461 | I50: 0.529 | J50: ='Cal Sheet'!E57 -> 0.22234014 | L50: Yes
B51: Britannia Industries Ltd | D51: NSE: BRITANNIA | E51: 104 | F51: 141739 | G51: =I51/(1+(H51*(1-'Input Sheet'!$C$17))) -> 0.36254819 | H51: ='Cal Sheet'!C58 -> 0.39948939 | I51: 0.471 | J51: ='Cal Sheet'!E58 -> 0.28031396 | L51: No
B52: Emami Ltd | D52: NSE: EMAMILTD | E52: 104 | F52: 22475 | G52: =I52/(1+(H52*(1-'Input Sheet'!$C$17))) -> 0.66754095 | H52: ='Cal Sheet'!C59 -> 0.024925341 | I52: 0.68 | J52: ='Cal Sheet'!E59 -> 0.024315754 | L52: Yes
B53: Bajaj Consumer Care Ltd | D53: NSE: BAJAJCON | E53: 104 | F53: 3665 | G53: =I53/(1+(H53*(1-'Input Sheet'!$C$17))) -> 0.827 | H53: ='Cal Sheet'!C60 -> 0 | I53: 0.827 | J53: ='Cal Sheet'!E60 -> 0 | L53: Yes
B55: Median - Broad Set | G55: =MEDIAN(G46:G53) -> 0.53159675 | H55: =MEDIAN(H46:H53) -> 0.062989783 | I55: =MEDIAN(I46:I53) -> 0.593 | J55: =MEDIAN(J46:J53) -> 0.057786006
B56: Average - Broad Set | G56: =AVERAGE(G46:G53) -> 0.57677248 | H56: =AVERAGE(H46:H53) -> 0.18321417 | I56: =AVERAGE(I46:I53) -> 0.6615 | J56: =AVERAGE(J46:J53) -> 0.12815529
B58: Median - Considered Set | G58: =MEDIAN(G46,G47,G50,G52:G53) -> 0.61445013 | H58: =MEDIAN(H46,H47,H50,H52:H53) -> 0.024925341 | I58: =MEDIAN(I46,I47,I50,I52:I53) -> 0.657 | J58: =MEDIAN(J46,J47,J50,J52:J53) -> 0.024315754
B59: Average - Considered Set | G59: =AVERAGE(G46:G47,G52:G53,G50) -> 0.5864781 | H59: =AVERAGE(H46:H47,H52:H53,H50) -> 0.080897608 | I59: =AVERAGE(I46:I47,I52:I53,I50) -> 0.6162 | J59: =AVERAGE(J46:J47,J52:J53,J50) -> 0.066193692
B63: Beta Analysis - 5 Years Monthly
...

Sheet Damodaran Data
B3: Country Data | G3: Company Data
B4: Country | C4: Africa | D4: Moody's rating | E4: Rating-based Default Spread | G4: For large non-financial service firms | L4: For smaller and riskier firms
B5: India | C5: Asia | D5: Baa3 | E5: 0.021609858 | G5: If interest coverage ratio is | L5: If interest coverage ratio is
B6: United Kingdom | C6: Western Europe | D6: Aa3 | E6: 0.0058935977 | G6: > | H6: ≤ to | I6: Rating is | J6: Spread is | L6: greater than | M6: ≤ to | N6: Rating is | O6: Spread is
B7: United States | C7: North America | D7: Aa1 | E7: 0.0027 | G7: -100000 | H7: 0.199999 | I7: D2/D | J7: 0.19 | L7: -100000 | M7: 0.499999 | N7: D2/D | O7: 0.19
B8: Abu Dhabi | C8: Middle East | D8: Aa2 | E8: 0.004853551 | G8: 0.2 | H8: 0.649999 | I8: C2/C | J8: 0.155 | L8: 0.5 | M8: 0.799999 | N8: C2/C | O8: 0.155
B9: Albania | C9: Eastern Europe & Russia | D9: Ba3 | E9: 0.035361586 | G9: 0.65 | H9: 0.799999 | I9: Ca2/CC | J9: 0.101 | L9: 0.8 | M9: 1.249999 | N9: Ca2/CC | O9: 0.101
B10: Andorra (Principality of) | C10: Western Europe | D10: Baa1 | E10: 0.015716261 | G10: 0.8 | H10: 1.249999 | I10: Caa/CCC | J10: 0.0728 | L10: 1.25 | M10: 1.499999 | N10: Caa/CCC | O10: 0.0728
B11: Angola | C11: Africa | D11: B3 | E11: 0.063905089 | G11: 1.25 | H11: 1.499999 | I11: B3/B- | J11: 0.0442 | L11: 1.5 | M11: 1.999999 | N11: B3/B- | O11: 0.0442
B12: Argentina | C12: Central and South America | D12: Caa3 | E12: 0.098342189 | G12: 1.5 | H12: 1.749999 | I12: B2/B | J12: 0.03 | L12: 2 | M12: 2.499999 | N12: B2/B | O12: 0.03
B13: Armenia | C13: Eastern Europe & Russia | D13: Ba3 | E13: 0.035361586 | G13: 1.75 | H13: 1.999999 | I13: B1/B+ | J13: 0.0261 | L13: 2.5 | M13: 2.999999 | N13: B1/B+ | O13: 0.0261
B14: Aruba | C14: Caribbean | D14: Baa3 | E14: 0.021609858 | G14: 2 | H14: 2.2499999 | I14: Ba2/BB | J14: 0.0183 | L14: 3 | M14: 3.499999 | N14: Ba2/BB | O14: 0.0183
B15: Australia | C15: Australia & New Zealand | D15: Aaa | E15: 0 | G15: 2.25 | H15: 2.49999 | I15: Ba1/BB+ | J15: 0.0155 | L15: 3.5 | M15: 3.9999999 | N15: Ba1/BB+ | O15: 0.0155
B16: Austria | C16: Western Europe | D16: Aa1 | E16: 0.0027 | G16: 2.5 | H16: 2.999999 | I16: Baa2/BBB | J16: 0.012 | L16: 4 | M16: 4.499999 | N16: Baa2/BBB | O16: 0.012
B17: Azerbaijan | C17: Eastern Europe & Russia | D17: Baa3 | E17: 0.021609858 | G17: 3 | H17: 4.249999 | I17: A3/A- | J17: 0.0095 | L17: 4.5 | M17: 5.999999 | N17: A3/A- | O17: 0.0095
B18: Bahamas | C18: Caribbean | D18: B1 | E18: 0.044259763 | G18: 4.25 | H18: 5.499999 | I18: A2/A | J18: 0.0085 | L18: 6 | M18: 7.499999 | N18: A2/A | O18: 0.0085
... B21: Barbados | C21: Caribbean | D21: B2 | E21: 0.054082426 | G21: 8.5 | H21: 100000 | I21: Aaa/AAA | J21: 0.0045 | L21: 12.5 | M21: 100000 | N21: Aaa/AAA | O21: 0.0045
B22: Belarus | C22: Eastern Europe & Russia | D22: C | E22: 0.175
B23: Belgium | C23: Western Europe | D23: Aa3 | E23: 0.0058935977
B24: Belize | C24: Central and South America | D24: Caa1 | E24: 0.073727752
B25: Benin | C25: Africa | D25: B1 | E25: 0.044259763
B26: Bermuda | C26: Caribbean | D26: A2 | E26: 0.0083203732
B27: Bolivia | C27: Central and South America | D27: Ca | E27: 0.11798751
B28: Bosnia and Herzegovina | C28: Eastern Europe & Russia | D28: B3 | E28: 0.063905089
B29: Botswana | C29: Africa | D29: A3 | E29: 0.011787195
B30: Brazil | C30: Central and South America | D30: Ba1 | E30: 0.024614437
B31: Bulgaria | C31: Eastern Europe & Russia | D31: Baa1 | E31: 0.015716261
B32: Burkina Faso | C32: Africa | D32: Caa1 | E32: 0.073727752
B33: Cambodia | C33: Asia | D33: B2 | E33: 0.054082426
... B161: Zambia | C161: Africa | D161: Caa2 | E161: 0.088519526

Sheet Assumptions Working 
A2: # | B2: Revenue Growth
B4: Company Historical Growth
K5: CAGR
B6: ='P&l 25-24'!B3 -> Particulars | C6: ='P&l 25-24'!D3 -> 43525 | D6: ='P&l 25-24'!E3 -> 43891 | E6: ='P&l 25-24'!F3 -> 44256 | F6: ='P&l 25-24'!G3 -> 44621 | G6: ='P&l 25-24'!H3 -> 44986 | H6: ='P&l 25-24'!I3 -> 45382 | I6: ='P&l 25-24'!J3 -> 45717 | K6: 3 Years | L6: 5 Years
B7: Revenue from operations (Net) | C7: 7334 | D7: 7315 | E7: 8048 | F7: 9512 | G7: 9764 | H7: 9653 | I7: 10831 | K7: =_xlfn.RRI(3,F7,I7) -> 0.044236585 | L7: =_xlfn.RRI(5,D7,I7) -> 0.081660188
B8: Sales Growth | C8: ='P&l 25-24'!D8 -> 0.16007593 | D8: ='P&l 25-24'!E8 -> -0.0025906736 | E8: ='P&l 25-24'!F8 -> 0.10020506 | F8: ='P&l 25-24'!G8 -> 0.18190855 | G8: ='P&l 25-24'!H8 -> 0.026492851 | H8: ='P&l 25-24'!I8 -> -0.011368292 | I8: ='P&l 25-24'!J8 -> 0.1220346
B11: FMCG (India) Growth
B13: Indian Brand Equity Foundation | C13: https://ibef.org/industry/fmcg-presentation
B15: Household FMCG ( April 2025) | C15: 17,792 crore (US$ 2.07 billion)
B16: Rural FMCG Consumption | C16: 35% of total FMCG sales | D16: 11% CAGR (premium segment)
B17: Indian Beauty and Personal Care (BPC) market | C17: $34 Bn by 2028 | D17: 10-11% Annual CAGR
B18: Overall FMCG Sector (India) | C18: US$ 615 billion (2027) | D18: 38.5% wil Grow till 2027
B19: Direct Selling Industry | C19: US$ 2.58 billion (FY24) | D19: 7.15% next (5-year CAGR)
B22: Crisil | C22: https://inciflo.com/blogs/fmcg-industry-growth-in-india/
B23: Indian FMCG industry | C23: $1trillion by 2033–34 | D23: 14–21%
B24: Rural markets | C24: 40% of FMCG sales by 2030
B25: Urban Markets | C25: 60% of FMCG sales by 2030
B26: E-commerce | C26: 15–18% FMCG sales by 2030,
B28: Imarc | C28: https://www.imarcgroup.com/india-fmcg-market
B29: 2024 Market Size | C29: USD 245.39 Billion
B30: 2033 Projected Market Size | C30: USD 1,108.48 Billion
B31: CAGR (2025-2033) | C31: 0.1733
B33: ZION Market Reserch | C33: https://www.zionmarketresearch.com/report/india-fmcg-market
B34: India FMCG market size | C34: USD 665.63 billion by 2032 | D34: (CAGR) 14.80%
B36: Beauty & Personal Care (India) Growth
B38: Statista | C38: https://www.statista.com/outlook/cmo/beauty-personal-care/india?srsltid=AfmBOorzt_p4jrJ6rhQpLXjwTHkLH4EGkU_rRtahTG4PhNxLzw7bm_L-
B39: Revenue | C39: US$33.08bn in 2025. | D39: 3.48% (CAGR 2025-2030)
B40: market volume | C40: US$14.80bn in 2025.
B41: United States | C41: (US$105bn in 2025)
B42: 9.4% of total revenue | C42: online sales by 2025.
B45: Indian Brand Equity Foundation | C45: https://www.ibef.org/news/india-you-e-beauty-the-blush-and-glow-of-the-new-billion-dollar-boom
AK46: BEAUTY AND PERSONAL CARE (BPC)
B47: India’s beauty and personal care market | C47: Rs. 2,95,358 crore (US$ 34 billion) by 2028, | D47: 10-11% Cagr Growth
B50: India Edible Oils (India) Growth
B52: Imarc | C52: https://www.imarcgroup.com/india-edible-oil-market
B54: 2024 Market Size | C54: 25.0 Million Tons
B55: 2033 Projected Market Size | C55: 28.2 Million Tons
B56: CAGR (2025-2033) | C56: 0.0131
B59: Industry Reports | C59: https://www.marketsandata.com/industry-reports/india-edible-oils-market
B61: FY2024 | C61: USD 19.86 billion
...

Sheet ControlSheet
B2: ='Input Sheet'!C5 -> Marico Ltd
B3: Control Sheet
J4: Current Case | K4: 1
J7: Actual | K7: Explicit Forecast Period | P7: Maturity Period
B8: In INR crores unless started otherwise | E8: 2020 | F8: =E8+1 -> 2021 | G8: =F8+1 -> 2022 | H8: =G8+1 -> 2023 | I8: =H8+1 -> 2024 | J8: =I8+1 -> 2025 | K8: =J8+1 -> 2026 | L8: =K8+1 -> 2027 | M8: =L8+1 -> 2028 | ... T8: =S8+1 -> 2035
B10: Assumptions
A12: # | B12: Revenue
B14: Revenue - yoy % Growth
B15: Management Case | E15: ='P&l 25-24'!E8 -> -0.0025906736 | F15: ='P&l 25-24'!F8 -> 0.10020506 | G15: ='P&l 25-24'!G8 -> 0.18190855 | H15: ='P&l 25-24'!H8 -> 0.026492851 | I15: ='P&l 25-24'!I8 -> -0.011368292 | J15: ='P&l 25-24'!J8 -> 0.1220346 | K15: 0.14 | L15: =K15+($O$15-$K$15)/($O$8-$K$8) -> 0.135 | M15: =L15+($O$15-$K$15)/($O$8-$K$8) -> 0.13 | N15: =M15+($O$15-$K$15)/($O$8-$K$8) -> 0.125 | O15: 0.12 | P15: 0.12 | Q15: 0.12 | R15: 0.12 | S15: 0.12 | T15: 0.12
B16: Base Case | E16: =E15 -> -0.0025906736 | F16: =F15 -> 0.10020506 | G16: =G15 -> 0.18190855 | H16: =H15 -> 0.026492851 | I16: =I15 -> -0.011368292 | J16: =J15 -> 0.1220346 | K16: 0.11 | L16: 0.11 | M16: 0.11 | N16: 0.11 | O16: 0.11 | P16: 0.1 | Q16: 0.1 | R16: 0.1 | S16: 0.1 | T16: 0.1
B17: Down Case | E17: =E16 -> -0.0025906736 | F17: =F16 -> 0.10020506 | G17: =G16 -> 0.18190855 | H17: =H16 -> 0.026492851 | I17: =I16 -> -0.011368292 | J17: =J16 -> 0.1220346 | K17: 0.1 | L17: 0.1 | M17: 0.1 | N17: 0.1 | O17: 0.1 | P17: 0.08 | Q17: 0.08 | R17: 0.08 | S17: 0.08 | T17: 0.08
B18: ="Current Case - "&CHOOSE($K$4,B15,B16,B17) -> Current Case - Management Case | K18: =CHOOSE($K$4,K15,K16,K17) -> 0.14 | L18: =CHOOSE($K$4,L15,L16,L17) -> 0.135 | M18: =CHOOSE($K$4,M15,M16,M17) -> 0.13 | N18: =CHOOSE($K$4,N15,N16,N17) -> 0.125 | O18: =CHOOSE($K$4,O15,O16,O17) -> 0.12 | P18: =CHOOSE($K$4,P15,P16,P17) -> 0.12 | Q18: =CHOOSE($K$4,Q15,Q16,Q17) -> 0.12 | R18: =CHOOSE($K$4,R15,R16,R17) -> 0.12 | ... T18: =CHOOSE($K$4,T15,T16,T17) -> 0.12
A21: # | B21: COGS
B23: Gross Margin %
B24: Management Case | E24: ='P&l 25-24'!D23 -> 0.45227707 | F24: ='P&l 25-24'!E23 -> 0.48803828 | G24: ='P&l 25-24'!F23 -> 0.4694334 | H24: ='P&l 25-24'!G23 -> 0.42851135 | I24: ='P&l 25-24'!H23 -> 0.45196641 | J24: ='P&l 25-24'!I23 -> 0.50813219 | K24: 0.48 | L24: 0.48 | M24: 0.48 | N24: 0.5 | O24: 0.5 | P24: 0.5 | Q24: 0.5 | R24: 0.5 | S24: 0.5 | T24: 0.5
B25: Base Case | E25: =E24 -> 0.45227707 | F25: =F24 -> 0.48803828 | G25: =G24 -> 0.4694334 | H25: =H24 -> 0.42851135 | I25: =I24 -> 0.45196641 | J25: =J24 -> 0.50813219 | K25: 0.45 | L25: 0.45 | M25: 0.45 | N25: 0.45 | O25: 0.45 | P25: 0.48 | Q25: 0.48 | R25: 0.48 | S25: 0.48 | T25: 0.48
B26: Down Case | E26: =E25 -> 0.45227707 | F26: =F25 -> 0.48803828 | G26: =G25 -> 0.4694334 | H26: =H25 -> 0.42851135 | I26: =I25 -> 0.45196641 | J26: =J25 -> 0.50813219 | K26: 0.43 | L26: 0.43 | M26: 0.43 | N26: 0.43 | O26: 0.43 | P26: 0.46 | Q26: 0.46 | R26: 0.46 | S26: 0.46 | T26: 0.46
B27: ="Current Case - "&CHOOSE($K$4,B24,B25,B26) -> Current Case - Management Case | K27: =CHOOSE($K$4,K24,K25,K26) -> 0.48 | L27: =CHOOSE($K$4,L24,L25,L26) -> 0.48 | M27: =CHOOSE($K$4,M24,M25,M26) -> 0.48 | N27: =CHOOSE($K$4,N24,N25,N26) -> 0.5 | O27: =CHOOSE($K$4,O24,O25,O26) -> 0.5 | P27: =CHOOSE($K$4,P24,P25,P26) -> 0.5 | Q27: =CHOOSE($K$4,Q24,Q25,Q26) -> 0.5 | R27: =CHOOSE($K$4,R24,R25,R26) -> 0.5 | ... T27: =CHOOSE($K$4,T24,T25,T26) -> 0.5
B29: Current Case - COGS % Sales | K29: =1-K27 -> 0.52 | L29: =1-L27 -> 0.52 | M29: =1-M27 -> 0.52 | N29: =1-N27 -> 0.5 | O29: =1-O27 -> 0.5 | P29: =1-P27 -> 0.5 | Q29: =1-Q27 -> 0.5 | R29: =1-R27 -> 0.5 | ... T29: =1-T27 -> 0.5
A31: # | B31: Selling, General and Administrative (SG&A) Expenses
B33: Employee Benefit Cost % Revenue
B34: Management Case | E34: ='Assumptions Working '!D245 -> 0.065345181 | F34: ='Assumptions Working '!E245 -> 0.07082505 | G34: ='Assumptions Working '!F245 -> 0.061606392 | H34: ='Assumptions Working '!G245 -> 0.066878329 | I34: ='Assumptions Working '!H245 -> 0.07697089 | J34: ='Assumptions Working '!I245 -> 0.076724218 | K34: 0.076 | L34: 0.076 | M34: 0.076 | N34: 0.076 | O34: 0.076 | P34: 0.076 | Q34: 0.076 | R34: 0.076 | S34: 0.076 | T34: 0.076
B35: Base Case | E35: =E34 -> 0.065345181 | F35: =F34 -> 0.07082505 | G35: =G34 -> 0.061606392 | H35: =H34 -> 0.066878329 | I35: =I34 -> 0.07697089 | J35: =J34 -> 0.076724218 | K35: 0.07 | L35: 0.07 | M35: 0.07 | N35: 0.07 | O35: 0.07 | P35: 0.07 | Q35: 0.07 | R35: 0.07 | S35: 0.07 | T35: 0.07
B36: Down Case | E36: =E35 -> 0.065345181 | F36: =F35 -> 0.07082505 | G36: =G35 -> 0.061606392 | H36: =H35 -> 0.066878329 | I36: =I35 -> 0.07697089 | J36: =J35 -> 0.076724218 | K36: 0.08 | L36: 0.08 | M36: 0.08 | N36: 0.08 | O36: 0.08 | P36: 0.08 | Q36: 0.08 | R36: 0.08 | S36: 0.08 | T36: 0.08
B37: ="Current Case - "&CHOOSE($K$4,B34,B35,B36) -> Current Case - Management Case | K37: =CHOOSE($K$4,K34,K35,K36) -> 0.076 | L37: =CHOOSE($K$4,L34,L35,L36) -> 0.076 | M37: =CHOOSE($K$4,M34,M35,M36) -> 0.076 | N37: =CHOOSE($K$4,N34,N35,N36) -> 0.076 | O37: =CHOOSE($K$4,O34,O35,O36) -> 0.076 | P37: =CHOOSE($K$4,P34,P35,P36) -> 0.076 | Q37: =CHOOSE($K$4,Q34,Q35,Q36) -> 0.076 | R37: =CHOOSE($K$4,R34,R35,R36) -> 0.076 | ... T37: =CHOOSE($K$4,T34,T35,T36) -> 0.076
B39: Advertisement and sales promotion % Revenue
B40: Management Case | E40: ='Assumptions Working '!D248 -> 0.099384826 | F40: ='Assumptions Working '!E248 -> 0.086729622 | G40: ='Assumptions Working '!F248 -> 0.083683768 | H40: ='Assumptions Working '!G248 -> 0.08623515 | I40: ='Assumptions Working '!H248 -> 0.09862219 | J40: ='Assumptions Working '!I248 -> 0.10414551 | K40: 0.115 | L40: 0.115 | M40: 0.115 | N40: 0.115 | O40: 0.115 | P40: 0.115 | Q40: 0.115 | R40: 0.115 | S40: 0.115 | T40: 0.115
B41: Base Case | E41: =E40 -> 0.099384826 | F41: =F40 -> 0.086729622 | G41: =G40 -> 0.083683768 | H41: =H40 -> 0.08623515 | I41: =I40 -> 0.09862219 | J41: =J40 -> 0.10414551 | K41: 0.09 | L41: 0.09 | M41: 0.09 | N41: 0.09 | O41: 0.09 | P41: 0.09 | Q41: 0.09 | R41: 0.09 | S41: 0.09 | T41: 0.09
B42: Down Case | E42: =E41 -> 0.099384826 | F42: =F41 -> 0.086729622 | G42: =G41 -> 0.083683768 | H42: =H41 -> 0.08623515 | I42: =I41 -> 0.09862219 | J42: =J41 -> 0.10414551 | K42: 0.1 | L42: 0.1 | M42: 0.1 | N42: 0.1 | O42: 0.1 | P42: 0.1 | Q42: 0.1 | R42: 0.1 | S42: 0.1 | T42: 0.1
B43: ="Current Case - "&CHOOSE($K$4,B40,B41,B42) -> Current Case - Management Case | K43: =CHOOSE($K$4,K40,K41,K42) -> 0.115 | L43: =CHOOSE($K$4,L40,L41,L42) -> 0.115 | M43: =CHOOSE($K$4,M40,M41,M42) -> 0.115 | N43: =CHOOSE($K$4,N40,N41,N42) -> 0.115 | O43: =CHOOSE($K$4,O40,O41,O42) -> 0.115 | P43: =CHOOSE($K$4,P40,P41,P42) -> 0.115 | Q43: =CHOOSE($K$4,Q40,Q41,Q42) -> 0.115 | R43: =CHOOSE($K$4,R40,R41,R42) -> 0.115 | ... T43: =CHOOSE($K$4,T40,T41,T42) -> 0.115
B45: Freight and distribution expenses % Revenue
B46: Management Case | E46: ='Assumptions Working '!D251 -> 0.040191388 | F46: ='Assumptions Working '!E251 -> 0.037897614 | G46: ='Assumptions Working '!F251 -> 0.037216148 | H46: ='Assumptions Working '!G251 -> 0.039635395 | I46: ='Assumptions Working '!H251 -> 0.043095411 | J46: ='Assumptions Working '!I251 -> 0.041455083 | K46: 0.04 | L46: 0.04 | M46: 0.04 | N46: 0.04 | O46: 0.04 | P46: 0.04 | Q46: 0.04 | R46: 0.04 | S46: 0.04 | T46: 0.04
B47: Base Case | E47: =E46 -> 0.040191388 | F47: =F46 -> 0.037897614 | G47: =G46 -> 0.037216148 | H47: =H46 -> 0.039635395 | I47: =I46 -> 0.043095411 | J47: =J46 -> 0.041455083 | K47: 0.036 | L47: 0.036 | M47: 0.036 | N47: 0.036 | O47: 0.036 | P47: 0.036 | Q47: 0.036 | R47: 0.036 | S47: 0.036 | T47: 0.036
B48: Down Case | E48: =E47 -> 0.040191388 | F48: =F47 -> 0.037897614 | G48: =G47 -> 0.037216148 | H48: =H47 -> 0.039635395 | I48: =I47 -> 0.043095411 | J48: =J47 -> 0.041455083 | K48: 0.036 | L48: 0.036 | M48: 0.036 | N48: 0.036 | O48: 0.036 | P48: 0.036 | Q48: 0.036 | R48: 0.036 | S48: 0.036 | T48: 0.036
B49: ="Current Case - "&CHOOSE($K$4,B46,B47,B48) -> Current Case - Management Case | K49: =CHOOSE($K$4,K46,K47,K48) -> 0.04 | L49: =CHOOSE($K$4,L46,L47,L48) -> 0.04 | M49: =CHOOSE($K$4,M46,M47,M48) -> 0.04 | N49: =CHOOSE($K$4,N46,N47,N48) -> 0.04 | O49: =CHOOSE($K$4,O46,O47,O48) -> 0.04 | P49: =CHOOSE($K$4,P46,P47,P48) -> 0.04 | Q49: =CHOOSE($K$4,Q46,Q47,Q48) -> 0.04 | R49: =CHOOSE($K$4,R46,R47,R48) -> 0.04 | ... T49: =CHOOSE($K$4,T46,T47,T48) -> 0.04
B51: Other Misc SG&A Expenses % Revenue
B52: Management Case | E52: ='Assumptions Working '!D254 -> 0.086261107 | F52: ='Assumptions Working '!E254 -> 0.074925447 | G52: ='Assumptions Working '!F254 -> 0.069280908 | H52: ='Assumptions Working '!G254 -> 0.073842687 | I52: ='Assumptions Working '!H254 -> 0.079560758 | J52: ='Assumptions Working '!I254 -> 0.08272551 | K52: 0.08 | L52: 0.08 | M52: 0.08 | N52: 0.08 | O52: 0.08 | P52: 0.08 | Q52: 0.08 | R52: 0.08 | S52: 0.08 | T52: 0.08
B53: Base Case | E53: =E52 -> 0.086261107 | F53: =F52 -> 0.074925447 | G53: =G52 -> 0.069280908 | H53: =H52 -> 0.073842687 | I53: =I52 -> 0.079560758 | J53: =J52 -> 0.08272551 | K53: 0.0729 | L53: 0.0729 | M53: 0.0729 | N53: 0.0729 | O53: 0.0729 | P53: 0.0729 | Q53: 0.0729 | R53: 0.0729 | S53: 0.0729 | T53: 0.0729
B54: Down Case | E54: =E53 -> 0.086261107 | F54: =F53 -> 0.074925447 | G54: =G53 -> 0.069280908 | H54: =H53 -> 0.073842687 | I54: =I53 -> 0.079560758 | J54: =J53 -> 0.08272551 | K54: 0.07 | L54: 0.07 | M54: 0.07 | N54: 0.07 | O54: 0.07 | P54: 0.07 | Q54: 0.07 | R54: 0.07 | S54: 0.07 | T54: 0.07
B55: ="Current Case - "&CHOOSE($K$4,B52,B53,B54) -> Current Case - Management Case | K55: =CHOOSE($K$4,K52,K53,K54) -> 0.08 | L55: =CHOOSE($K$4,L52,L53,L54) -> 0.08 | M55: =CHOOSE($K$4,M52,M53,M54) -> 0.08 | N55: =CHOOSE($K$4,N52,N53,N54) -> 0.08 | O55: =CHOOSE($K$4,O52,O53,O54) -> 0.08 | P55: =CHOOSE($K$4,P52,P53,P54) -> 0.08 | Q55: =CHOOSE($K$4,Q52,Q53,Q54) -> 0.08 | R55: =CHOOSE($K$4,R52,R53,R54) -> 0.08 | ... T55: =CHOOSE($K$4,T52,T53,T54) -> 0.08
...

Sheet Schedules
B2: ='Input Sheet'!C5 -> Marico Ltd
B3: Schedules
I4: Current Case
I8: Actual | J8: Explicit Forecast Period | O8: Maturity Period
B9: In INR crores unless started otherwise | D9: =ControlSheet!E8 -> 2020 | E9: =ControlSheet!F8 -> 2021 | F9: =ControlSheet!G8 -> 2022 | G9: =ControlSheet!H8 -> 2023 | H9: =ControlSheet!I8 -> 2024 | I9: =ControlSheet!J8 -> 2025 | J9: =ControlSheet!K8 -> 2026 | K9: =ControlSheet!L8 -> 2027 | ... S9: =ControlSheet!T8 -> 2035
A11: # | B11: Revenue Schedules
B13: Revenue | D13: ='P&l 25-24'!E6 -> 7315 | E13: ='P&l 25-24'!F6 -> 8048 | F13: ='P&l 25-24'!G6 -> 9512 | G13: ='P&l 25-24'!H6 -> 9764 | H13: ='P&l 25-24'!I6 -> 9653 | I13: ='P&l 25-24'!J6 -> 10831 | J13: =I13*(1+J15) -> 12347.34 | K13: =J13*(1+K15) -> 14014.231 | L13: =K13*(1+L15) -> 15836.081 | M13: =L13*(1+M15) -> 17815.591 | N13: =M13*(1+N15) -> 19953.462 | O13: =N13*(1+O15) -> 22347.877 | P13: =O13*(1+P15) -> 25029.623 | Q13: =P13*(1+Q15) -> 28033.177 | ... S13: =R13*(1+S15) -> 35164.818
B15: Growth YoY | E15: =E13/D13-1 -> 0.10020506 | F15: =F13/E13-1 -> 0.18190855 | G15: =G13/F13-1 -> 0.026492851 | H15: =H13/G13-1 -> -0.011368292 | I15: =I13/H13-1 -> 0.1220346 | J15: =ControlSheet!K18 -> 0.14 | K15: =ControlSheet!L18 -> 0.135 | L15: =ControlSheet!M18 -> 0.13 | M15: =ControlSheet!N18 -> 0.125 | N15: =ControlSheet!O18 -> 0.12 | O15: =ControlSheet!P18 -> 0.12 | P15: =ControlSheet!Q18 -> 0.12 | Q15: =ControlSheet!R18 -> 0.12 | ... S15: =ControlSheet!T18 -> 0.12
A17: # | B17: COGS Schedules
B20: COGS | D20: ='P&l 25-24'!E16*-1 -> 3745 | E20: ='P&l 25-24'!F16*-1 -> 4270 | F20: ='P&l 25-24'!G16*-1 -> 5436 | G20: ='P&l 25-24'!H16*-1 -> 5351 | H20: ='P&l 25-24'!I16*-1 -> 4748 | I20: ='P&l 25-24'!J16*-1 -> 5388 | J20: =J13*J22 -> 6420.6168 | K20: =K13*K22 -> 7287.4001 | L20: =L13*L22 -> 8234.7621 | M20: =M13*M22 -> 8907.7955 | N20: =N13*N22 -> 9976.731 | O20: =O13*O22 -> 11173.939 | P20: =P13*P22 -> 12514.811 | Q20: =Q13*Q22 -> 14016.589 | ... S20: =S13*S22 -> 17582.409
B22: COGS % Sales | D22: =D20/D13 -> 0.51196172 | E22: =E20/E13 -> 0.5305666 | F22: =F20/F13 -> 0.57148865 | G22: =G20/G13 -> 0.54803359 | H22: =H20/H13 -> 0.49186781 | I22: =I20/I13 -> 0.49746099 | J22: =ControlSheet!K29 -> 0.52 | K22: =ControlSheet!L29 -> 0.52 | L22: =ControlSheet!M29 -> 0.52 | M22: =ControlSheet!N29 -> 0.5 | N22: =ControlSheet!O29 -> 0.5 | O22: =ControlSheet!P29 -> 0.5 | P22: =ControlSheet!Q29 -> 0.5 | Q22: =ControlSheet!R29 -> 0.5 | ... S22: =ControlSheet!T29 -> 0.5
A24: # | B24: SG&A (Excluding Depreciation & Interest Expenses) Schedules
B26: Employee Benefit Cost
B28: Employee Benefit Cost | D28: ='Assumptions Working '!D203 -> 478 | E28: ='Assumptions Working '!E203 -> 570 | F28: ='Assumptions Working '!F203 -> 586 | G28: ='Assumptions Working '!G203 -> 653 | H28: ='Assumptions Working '!H203 -> 743 | I28: ='Assumptions Working '!I203 -> 831 | J28: =J$13*J29 -> 938.39784 | K28: =K$13*K29 -> 1065.0815 | L28: =L$13*L29 -> 1203.5421 | M28: =M$13*M29 -> 1353.9849 | N28: =N$13*N29 -> 1516.4631 | O28: =O$13*O29 -> 1698.4387 | P28: =P$13*P29 -> 1902.2513 | Q28: =Q$13*Q29 -> 2130.5215 | ... S28: =S$13*S29 -> 2672.5261
B29: Employee Benefit Cost % Revenue | D29: ='Assumptions Working '!D245 -> 0.065345181 | E29: ='Assumptions Working '!E245 -> 0.07082505 | F29: ='Assumptions Working '!F245 -> 0.061606392 | G29: ='Assumptions Working '!G245 -> 0.066878329 | H29: ='Assumptions Working '!H245 -> 0.07697089 | I29: ='Assumptions Working '!I245 -> 0.076724218 | J29: =ControlSheet!K37 -> 0.076 | K29: =ControlSheet!L37 -> 0.076 | L29: =ControlSheet!M37 -> 0.076 | M29: =ControlSheet!N37 -> 0.076 | N29: =ControlSheet!O37 -> 0.076 | O29: =ControlSheet!P37 -> 0.076 | P29: =ControlSheet!Q37 -> 0.076 | Q29: =ControlSheet!R37 -> 0.076 | ... S29: =ControlSheet!T37 -> 0.076
B31: Advertisement and sales promotion
B33: Advertisement and sales promotion | D33: ='Assumptions Working '!D204 -> 727 | E33: ='Assumptions Working '!E204 -> 698 | F33: ='Assumptions Working '!F204 -> 796 | G33: ='Assumptions Working '!G204 -> 842 | H33: ='Assumptions Working '!H204 -> 952 | I33: ='Assumptions Working '!I204 -> 1128 | J33: =J$13*J34 -> 1419.9441 | K33: =K$13*K34 -> 1611.6366 | L33: =L$13*L34 -> 1821.1493 | M33: =M$13*M34 -> 2048.793 | N33: =N$13*N34 -> 2294.6481 | O33: =O$13*O34 -> 2570.0059 | P33: =P$13*P34 -> 2878.4066 | Q33: =Q$13*Q34 -> 3223.8154 | ... S33: =S$13*S34 -> 4043.954
B34: Advertisement and sales promotion % Revenue | D34: ='Assumptions Working '!D248 -> 0.099384826 | E34: ='Assumptions Working '!E248 -> 0.086729622 | F34: ='Assumptions Working '!F248 -> 0.083683768 | G34: ='Assumptions Working '!G248 -> 0.08623515 | H34: ='Assumptions Working '!H248 -> 0.09862219 | I34: ='Assumptions Working '!I248 -> 0.10414551 | J34: =ControlSheet!K43 -> 0.115 | K34: =ControlSheet!L43 -> 0.115 | L34: =ControlSheet!M43 -> 0.115 | M34: =ControlSheet!N43 -> 0.115 | N34: =ControlSheet!O43 -> 0.115 | O34: =ControlSheet!P43 -> 0.115 | P34: =ControlSheet!Q43 -> 0.115 | Q34: =ControlSheet!R43 -> 0.115 | ... S34: =ControlSheet!T43 -> 0.115
B36: Freight and distribution expenses
B38: Freight and distribution expenses | D38: ='Assumptions Working '!D205 -> 294 | E38: ='Assumptions Working '!E205 -> 305 | F38: ='Assumptions Working '!F205 -> 354 | G38: ='Assumptions Working '!G205 -> 387 | H38: ='Assumptions Working '!H205 -> 416 | I38: ='Assumptions Working '!I205 -> 449 | J38: =J$13*J39 -> 493.8936 | K38: =K$13*K39 -> 560.56924 | L38: =L$13*L39 -> 633.44324 | M38: =M$13*M39 -> 712.62364 | N38: =N$13*N39 -> 798.13848 | O38: =O$13*O39 -> 893.9151 | P38: =P$13*P39 -> 1001.1849 | Q38: =Q$13*Q39 -> 1121.3271 | ... S38: =S$13*S39 -> 1406.5927
B39: Freight and distribution expenses % Revenue | D39: ='Assumptions Working '!D251 -> 0.040191388 | E39: ='Assumptions Working '!E251 -> 0.037897614 | F39: ='Assumptions Working '!F251 -> 0.037216148 | G39: ='Assumptions Working '!G251 -> 0.039635395 | H39: ='Assumptions Working '!H251 -> 0.043095411 | I39: ='Assumptions Working '!I251 -> 0.041455083 | J39: =ControlSheet!K49 -> 0.04 | K39: =ControlSheet!L49 -> 0.04 | L39: =ControlSheet!M49 -> 0.04 | M39: =ControlSheet!N49 -> 0.04 | N39: =ControlSheet!O49 -> 0.04 | O39: =ControlSheet!P49 -> 0.04 | P39: =ControlSheet!Q49 -> 0.04 | Q39: =ControlSheet!R49 -> 0.04 | ... S39: =ControlSheet!T49 -> 0.04
B41: Other Misc SG&A Expenses
B43: Other Misc SG&A Expenses | D43: ='Assumptions Working '!D253 -> 631 | E43: ='Assumptions Working '!E253 -> 603 | F43: ='Assumptions Working '!F253 -> 659 | G43: ='Assumptions Working '!G253 -> 721 | H43: ='Assumptions Working '!H253 -> 768 | I43: ='Assumptions Working '!I253 -> 896 | J43: =J$13*J44 -> 987.7872 | K43: =K$13*K44 -> 1121.1385 | L43: =L$13*L44 -> 1266.8865 | M43: =M$13*M44 -> 1425.2473 | N43: =N$13*N44 -> 1596.277 | O43: =O$13*O44 -> 1787.8302 | P43: =P$13*P44 -> 2002.3698 | Q43: =Q$13*Q44 -> 2242.6542 | ... S43: =S$13*S44 -> 2813.1854
B44: Other Misc SG&A Expenses % Revenue | D44: ='Assumptions Working '!C254 -> 0.07908372 | E44: ='Assumptions Working '!D254 -> 0.086261107 | F44: ='Assumptions Working '!E254 -> 0.074925447 | G44: ='Assumptions Working '!F254 -> 0.069280908 | H44: ='Assumptions Working '!G254 -> 0.073842687 | I44: ='Assumptions Working '!H254 -> 0.079560758 | J44: =ControlSheet!K55 -> 0.08 | K44: =ControlSheet!L55 -> 0.08 | L44: =ControlSheet!M55 -> 0.08 | M44: =ControlSheet!N55 -> 0.08 | N44: =ControlSheet!O55 -> 0.08 | O44: =ControlSheet!P55 -> 0.08 | P44: =ControlSheet!Q55 -> 0.08 | Q44: =ControlSheet!R55 -> 0.08 | ... S44: =ControlSheet!T55 -> 0.08
B46: Total SG&A (Excluding Depreciation & Interest Expenses) Schedules | D46: =D43+D38+D33+D28 -> 2130 | E46: =E43+E38+E33+E28 -> 2176 | F46: =F43+F38+F33+F28 -> 2395 | G46: =G43+G38+G33+G28 -> 2603 | H46: =H43+H38+H33+H28 -> 2879 | I46: =I43+I38+I33+I28 -> 3304 | J46: =J43+J38+J33+J28 -> 3840.0227 | K46: =K43+K38+K33+K28 -> 4358.4258 | ... S46: =S43+S38+S33+S28 -> 10936.258
B47: Total SG&A % Sales | D47: =D46/D$13 -> 0.2911825 | E47: =E46/E$13 -> 0.27037773 | F47: =F46/F$13 -> 0.25178722 | G47: =G46/G$13 -> 0.26659156 | H47: =H46/H$13 -> 0.29824925 | I47: =I46/I$13 -> 0.30505032 | J47: =J46/J$13 -> 0.311 | K47: =K46/K$13 -> 0.311 | ... S47: =S46/S$13 -> 0.311
A49: # | B49: Non Current Asset Schedules
B51: Property, Plant & Equipments
B53: Opening PP&E | D53: ='Balance Sheet'!C8 -> 572 | E53: ='Balance Sheet'!D8 -> 654 | F53: ='Balance Sheet'!E8 -> 572 | G53: ='Balance Sheet'!F8 -> 600 | H53: ='Balance Sheet'!G8 -> 633 | I53: ='Balance Sheet'!H8 -> 700 | J53: ='Balance Sheet'!I8 -> 710 | K53: =J56 -> 780.38694 | L53: =K56 -> 862.49563 | M53: =L56 -> 956.8621 | N53: =M56 -> 1063.8974 | O53: =N56 -> 1165.2318 | P53: =O56 -> 1280.1345 | Q53: =P56 -> 1433.5947 | R53: =Q56 -> 1631.374 | S53: =R56 -> 1806.8016
B54: ADD: Capex during the Year | J54: ='Assumptions Working '!C524 -> 197.55744 | K54: ='Assumptions Working '!D524 -> 224.22769 | L54: ='Assumptions Working '!E524 -> 253.37729 | M54: ='Assumptions Working '!F524 -> 285.04946 | N54: ='Assumptions Working '!G524 -> 299.30193 | O54: ='Assumptions Working '!H524 -> 335.21816 | P54: ='Assumptions Working '!I524 -> 400.47396 | Q54: ='Assumptions Working '!J524 -> 476.56402 | ... S54: ='Assumptions Working '!L524 -> 439.56022
B55: Less: Depreciation | I55: 114 | J55: =I55+J54/$C$109 -> 127.1705 | K55: =J55+K54/$C$109 -> 142.11901 | L55: =K55+L54/$C$109 -> 159.01083 | M55: =L55+M54/$C$109 -> 178.01413 | N55: =M55+N54/$C$109 -> 197.96759 | O55: =N55+O54/$C$109 -> 220.31547 | P55: =O55+P54/$C$109 -> 247.01373 | Q55: =P55+Q54/$C$109 -> 278.78466 | ... S55: =R55+S54/$C$109 -> 340.53241
B56: Closing PPE | J56: =J53+J54-J55 -> 780.38694 | K56: =K53+K54-K55 -> 862.49563 | L56: =L53+L54-L55 -> 956.8621 | M56: =M53+M54-M55 -> 1063.8974 | N56: =N53+N54-N55 -> 1165.2318 | O56: =O53+O54-O55 -> 1280.1345 | P56: =P53+P54-P55 -> 1433.5947 | Q56: =Q53+Q54-Q55 -> 1631.374 | ... S56: =S53+S54-S55 -> 1905.8294
B57: YoY Growth % | K57: =K56/J56-1 -> 0.10521535 | L57: =L56/K56-1 -> 0.10941095 | M57: =M56/L56-1 -> 0.11186077 | N57: =N56/M56-1 -> 0.095248225 | O57: =O56/N56-1 -> 0.098609306 | P57: =P56/O56-1 -> 0.11987821 | Q57: =Q56/P56-1 -> 0.13796044 | R57: =R56/Q56-1 -> 0.10753363 | S57: =S56/R56-1 -> 0.054808348
B59: Right of Use Asset
B60: Right of Use Asset | D60: ='Balance Sheet'!C10 -> 153 | E60: ='Balance Sheet'!D10 -> 146 | F60: ='Balance Sheet'!E10 -> 180 | G60: ='Balance Sheet'!F10 -> 178 | H60: ='Balance Sheet'!G10 -> 175 | I60: ='Balance Sheet'!H10 -> 209 | J60: ='Balance Sheet'!I10 -> 230 | K60: =J63 -> 177 | L60: =K63 -> 124 | M60: =L63 -> 71 | N60: =M63 -> 18 | O60: =N63 -> 0 | P60: =O63 -> 0 | Q60: =P63 -> 0 | R60: =Q63 -> 0 | S60: =R63 -> 0
B61: Additional during the Year | J61: 0 | K61: 0 | L61: 0 | M61: 0 | N61: 0 | O61: 0 | P61: 0 | Q61: 0 | R61: 0 | S61: 0
B62: Less: Depreciation | I62: 53 | J62: =I62+J61/$C$109 -> 53 | K62: =J62+K61/$C$109 -> 53 | L62: =K62+L61/$C$109 -> 53 | M62: =L62+M61/$C$109 -> 53 | N62: 18 | O62: 0 | P62: 0 | Q62: 0 | R62: 0 | S62: 0
B63: Closing ROU Asset | J63: =J60+J61-J62 -> 177 | K63: =K60+K61-K62 -> 124 | L63: =L60+L61-L62 -> 71 | M63: =M60+M61-M62 -> 18 | N63: =N60+N61-N62 -> 0 | O63: =O60+O61-O62 -> 0 | P63: =P60+P61-P62 -> 0 | Q63: =Q60+Q61-Q62 -> 0 | ... S63: =S60+S61-S62 -> 0
B64: YoY Growth % | K64: =K63/J63-1 -> -0.29943503 | L64: =L63/K63-1 -> -0.42741935 | M64: =M63/L63-1 -> -0.74647887 | N64: =N63/M63-1 -> -1 | O64: =IF(N63=0, 0, (O63/N63)-1) -> 0 | P64: =IF(O63=0, 0, (P63/O63)-1) -> 0 | Q64: =IF(P63=0, 0, (Q63/P63)-1) -> 0 | R64: =IF(Q63=0, 0, (R63/Q63)-1) -> 0 | S64: =IF(R63=0, 0, (S63/R63)-1) -> 0
B66: YoY Growth % | J66: =ControlSheet!K69 -> 0 | K66: =ControlSheet!L69 -> 0 | L66: =ControlSheet!M69 -> 0 | M66: =ControlSheet!N69 -> 0 | N66: =ControlSheet!O69 -> 0 | O66: =ControlSheet!P69 -> 0 | P66: =ControlSheet!Q69 -> 0 | Q66: =ControlSheet!R69 -> 0 | ... S66: =ControlSheet!T69 -> 0
...

Sheet 3 Statement Model
B2: ='Input Sheet'!C5 -> Marico Ltd
B3: 3 Statement Model
K4: Current Case
D8: Actual | J8: Explicit Forecast Period | O8: Maturity Period | U8: 5 Year | V8: 3 Year
B9: In INR crores unless started otherwise | D9: =Schedules!D9 -> 2020 | E9: =Schedules!E9 -> 2021 | F9: =Schedules!F9 -> 2022 | G9: =Schedules!G9 -> 2023 | H9: =Schedules!H9 -> 2024 | I9: =Schedules!I9 -> 2025 | J9: =I9+1 -> 2026 | K9: =J9+1 -> 2027 | L9: =K9+1 -> 2028 | M9: =L9+1 -> 2029 | N9: =M9+1 -> 2030 | O9: =N9+1 -> 2031 | P9: =O9+1 -> 2032 | Q9: =P9+1 -> 2033 | ... S9: =R9+1 -> 2035
A11: # | B11: Income Statement
B13: Revenue | D13: =Schedules!D13 -> 7315 | E13: =Schedules!E13 -> 8048 | F13: =Schedules!F13 -> 9512 | G13: =Schedules!G13 -> 9764 | H13: =Schedules!H13 -> 9653 | I13: =Schedules!I13 -> 10831 | J13: =Schedules!J13 -> 12347.34 | K13: =Schedules!K13 -> 14014.231 | ... S13: =Schedules!S13 -> 35164.818 | U13: =_xlfn.RRI(5,I13,N13) -> 0.12997788 | V13: =_xlfn.RRI(3,K13,N13) -> 0.12499259
B14: Less: Cost of Goods Sold | D14: =Schedules!D20 -> 3745 | E14: =Schedules!E20 -> 4270 | F14: =Schedules!F20 -> 5436 | G14: =Schedules!G20 -> 5351 | H14: =Schedules!H20 -> 4748 | I14: =Schedules!I20 -> 5388 | J14: =Schedules!J20 -> 6420.6168 | K14: =Schedules!K20 -> 7287.4001 | ... S14: =Schedules!S20 -> 17582.409 | U14: =_xlfn.RRI(5,I14,N14) -> 0.13112899 | V14: =_xlfn.RRI(3,K14,N14) -> 0.11038065
B15: Gross Profit | D15: =D13-D14 -> 3570 | E15: =E13-E14 -> 3778 | F15: =F13-F14 -> 4076 | G15: =G13-G14 -> 4413 | H15: =H13-H14 -> 4905 | I15: =I13-I14 -> 5443 | J15: =J13-J14 -> 5926.7232 | K15: =K13-K14 -> 6726.8308 | ... S15: =S13-S14 -> 17582.409 | U15: =_xlfn.RRI(5,I15,N15) -> 0.12883375 | V15: =_xlfn.RRI(3,K15,N15) -> 0.14040537
B17: Gross Margin | D17: =D15/D13 -> 0.48803828 | E17: =E15/E13 -> 0.4694334 | F17: =F15/F13 -> 0.42851135 | G17: =G15/G13 -> 0.45196641 | H17: =H15/H13 -> 0.50813219 | I17: =I15/I13 -> 0.50253901 | J17: =J15/J13 -> 0.48 | K17: =K15/K13 -> 0.48 | ... S17: =S15/S13 -> 0.5
B19: Less: SG&A Expenses (Excluding Depreciation & Interest)
B20: =Schedules!B26 -> Employee Benefit Cost | D20: =Schedules!D28 -> 478 | E20: =Schedules!E28 -> 570 | F20: =Schedules!F28 -> 586 | G20: =Schedules!G28 -> 653 | H20: =Schedules!H28 -> 743 | I20: =Schedules!I28 -> 831 | J20: =Schedules!J28 -> 938.39784 | K20: =Schedules!K28 -> 1065.0815 | ... S20: =Schedules!S28 -> 2672.5261 | U20: =_xlfn.RRI(5,I20,N20) -> 0.12783655 | V20: =_xlfn.RRI(3,K20,N20) -> 0.12499259
B21: =Schedules!B31 -> Advertisement and sales promotion | D21: =Schedules!D33 -> 727 | E21: =Schedules!E33 -> 698 | F21: =Schedules!F33 -> 796 | G21: =Schedules!G33 -> 842 | H21: =Schedules!H33 -> 952 | I21: =Schedules!I33 -> 1128 | J21: =Schedules!J33 -> 1419.9441 | K21: =Schedules!K33 -> 1611.6366 | ... S21: =Schedules!S33 -> 4043.954 | U21: =_xlfn.RRI(5,I21,N21) -> 0.15260739 | V21: =_xlfn.RRI(3,K21,N21) -> 0.12499259
B22: =Schedules!B36 -> Freight and distribution expenses | D22: =Schedules!D38 -> 294 | E22: =Schedules!E38 -> 305 | F22: =Schedules!F38 -> 354 | G22: =Schedules!G38 -> 387 | H22: =Schedules!H38 -> 416 | I22: =Schedules!I38 -> 449 | J22: =Schedules!J38 -> 493.8936 | K22: =Schedules!K38 -> 560.56924 | ... S22: =Schedules!S38 -> 1406.5927 | U22: =_xlfn.RRI(5,I22,N22) -> 0.1219316 | V22: =_xlfn.RRI(3,K22,N22) -> 0.12499259
B23: =Schedules!B41 -> Other Misc SG&A Expenses | D23: =Schedules!D43 -> 631 | E23: =Schedules!E43 -> 603 | F23: =Schedules!F43 -> 659 | G23: =Schedules!G43 -> 721 | H23: =Schedules!H43 -> 768 | I23: =Schedules!I43 -> 896 | J23: =Schedules!J43 -> 987.7872 | K23: =Schedules!K43 -> 1121.1385 | ... S23: =Schedules!S43 -> 2813.1854 | U23: =_xlfn.RRI(5,I23,N23) -> 0.12243202 | V23: =_xlfn.RRI(3,K23,N23) -> 0.12499259
B25: EBITDA | D25: =D15-SUM(D20:D23) -> 1440 | E25: =E15-SUM(E20:E23) -> 1602 | F25: =F15-SUM(F20:F23) -> 1681 | G25: =G15-SUM(G20:G23) -> 1810 | H25: =H15-SUM(H20:H23) -> 2026 | I25: =I15-SUM(I20:I23) -> 2139 | J25: =J15-SUM(J20:J23) -> 2086.7005 | K25: =K15-SUM(K20:K23) -> 2368.405 | ... S25: =S15-SUM(S20:S23) -> 6646.1506 | U25: =_xlfn.RRI(5,I25,N25) -> 0.12009241 | V25: =_xlfn.RRI(3,K25,N25) -> 0.16772711
B27: EBITDA | D27: =D25/D13 -> 0.19685578 | E27: =E25/E13 -> 0.19905567 | F27: =F25/F13 -> 0.17672414 | G27: =G25/G13 -> 0.18537485 | H27: =H25/H13 -> 0.20988294 | I27: =I25/I13 -> 0.19748869 | J27: =J25/J13 -> 0.169 | K27: =K25/K13 -> 0.169 | ... S27: =S25/S13 -> 0.189
B29: Less: Depreciation & Amortization | D29: ='P&l 25-24'!E36*-1 -> 140 | E29: ='P&l 25-24'!F36*-1 -> 139 | F29: ='P&l 25-24'!G36*-1 -> 139 | G29: ='P&l 25-24'!H36*-1 -> 155 | H29: ='P&l 25-24'!I36*-1 -> 158 | I29: ='P&l 25-24'!J36*-1 -> 178 | J29: =Schedules!J110 -> 191.1705 | K29: =Schedules!K110 -> 206.11901 | L29: =Schedules!L110 -> 223.01083 | M29: =Schedules!M110 -> 242.01413 | N29: =Schedules!N110 -> 226.96759 | O29: =Schedules!O110 -> 231.31547 | P29: =Schedules!P110 -> 258.01373 | Q29: =Schedules!Q110 -> 289.78466 | ... S29: =Schedules!S110 -> 351.53241 | U29: =_xlfn.RRI(5,I29,N29) -> 0.049805317 | V29: =_xlfn.RRI(3,K29,N29) -> 0.03263918
B30: EBIT | D30: =D25-D29 -> 1300 | E30: =E25-E29 -> 1463 | F30: =F25-F29 -> 1542 | G30: =G25-G29 -> 1655 | H30: =H25-H29 -> 1868 | I30: =I25-I29 -> 1961 | J30: =J25-J29 -> 1895.53 | K30: =K25-K29 -> 2162.286 | ... S30: =S25-S29 -> 6294.6181 | U30: =_xlfn.RRI(5,I30,N30) -> 0.12566464 | V30: =_xlfn.RRI(3,K30,N30) -> 0.17906169
B32: EBIT Margin | D32: =D30/D13 -> 0.17771702 | E32: =E30/E13 -> 0.18178429 | F32: =F30/F13 -> 0.16211102 | G32: =G30/G13 -> 0.1695002 | H32: =H30/H13 -> 0.19351497 | I32: =I30/I13 -> 0.18105438 | J32: =J30/J13 -> 0.15351727 | K32: =K30/K13 -> 0.15429216 | ... S32: =S30/S13 -> 0.17900329
B34: Less: Interest | D34: ='P&l 25-24'!E39*-1 -> 50 | E34: ='P&l 25-24'!F39*-1 -> 34 | F34: ='P&l 25-24'!G39*-1 -> 39 | G34: ='P&l 25-24'!H39*-1 -> 56 | H34: ='P&l 25-24'!I39*-1 -> 73 | I34: ='P&l 25-24'!J39*-1 -> 53 | J34: =Schedules!J244 -> 54.55585 | K34: =Schedules!K244 -> 65.903927 | L34: =Schedules!L244 -> 64.728229 | M34: =Schedules!M244 -> 63.096885 | N34: =Schedules!N244 -> 70.816974 | O34: =Schedules!O244 -> 72.470974 | P34: =Schedules!P244 -> 74.167018 | Q34: =Schedules!Q244 -> 82.910625 | ... S34: =Schedules!S244 -> 104.00309 | U34: =_xlfn.RRI(5,I34,N34) -> 0.059674051 | V34: =_xlfn.RRI(3,K34,N34) -> 0.024256411
B35: Add: Other Income | D35: ='P&l 25-24'!E40 -> 124 | E35: ='P&l 25-24'!F40 -> 94 | F35: ='P&l 25-24'!G40 -> 98 | G35: ='P&l 25-24'!H40 -> 144 | H35: ='P&l 25-24'!I40 -> 142 | I35: ='P&l 25-24'!J40 -> 208 | J35: =Schedules!J250 -> 185.2101 | K35: =Schedules!K250 -> 210.21346 | L35: =Schedules!L250 -> 237.54121 | M35: =Schedules!M250 -> 267.23387 | N35: =Schedules!N250 -> 299.30193 | O35: =Schedules!O250 -> 335.21816 | P35: =Schedules!P250 -> 375.44434 | Q35: =Schedules!Q250 -> 420.49766 | ... S35: =Schedules!S250 -> 527.47227 | U35: =_xlfn.RRI(5,I35,N35) -> 0.075497082 | V35: =_xlfn.RRI(3,K35,N35) -> 0.12499259
B36: EBT | D36: =D30-D34+D35 -> 1374 | E36: =E30-E34+E35 -> 1523 | F36: =F30-F34+F35 -> 1601 | G36: =G30-G34+G35 -> 1743 | H36: =H30-H34+H35 -> 1937 | I36: =I30-I34+I35 -> 2116 | J36: =J30-J34+J35 -> 2026.1842 | K36: =K30-K34+K35 -> 2306.5955 | ... S36: =S30-S34+S35 -> 6718.0873 | U36: =_xlfn.RRI(5,I36,N36) -> 0.12260719 | V36: =_xlfn.RRI(3,K36,N36) -> 0.17822375
B38: Less: Taxes | D38: ='P&l 25-24'!E44*-1 -> 331 | E38: ='P&l 25-24'!F44*-1 -> 324 | F38: ='P&l 25-24'!G44*-1 -> 346 | G38: ='P&l 25-24'!H44*-1 -> 421 | H38: ='P&l 25-24'!I44*-1 -> 435 | I38: ='P&l 25-24'!J44*-1 -> 458 | J38: =Schedules!J136 -> 508.97747 | K38: =Schedules!K136 -> 579.4168 | L38: =Schedules!L136 -> 659.67628 | M38: =Schedules!M136 -> 836.31251 | N38: =Schedules!N136 -> 947.70769 | O38: =Schedules!O136 -> 1068.9014 | P38: =Schedules!P136 -> 1199.1942 | Q38: =Schedules!Q136 -> 1342.9335 | ... S38: =Schedules!S136 -> 1687.5835 | U38: =_xlfn.RRI(5,I38,N38) -> 0.156543 | V38: =_xlfn.RRI(3,K38,N38) -> 0.17822375
B39: Net Income | D39: =D36-D38 -> 1043 | E39: =E36-E38 -> 1199 | F39: =F36-F38 -> 1255 | G39: =G36-G38 -> 1322 | H39: =H36-H38 -> 1502 | I39: =I36-I38 -> 1658 | J39: =J36-J38 -> 1517.2067 | K39: =K36-K38 -> 1727.1787 | ... S39: =S36-S38 -> 5030.5038 | U39: =_xlfn.RRI(5,I39,N39) -> 0.1124672 | V39: =_xlfn.RRI(3,K39,N39) -> 0.17822375
B41: Sales Growth % | D41: NM | E41: =E13/D13-1 -> 0.10020506 | F41: =F13/E13-1 -> 0.18190855 | G41: =G13/F13-1 -> 0.026492851 | H41: =H13/G13-1 -> -0.011368292 | I41: =I13/H13-1 -> 0.1220346 | J41: =J13/I13-1 -> 0.14 | K41: =K13/J13-1 -> 0.135 | L41: =L13/K13-1 -> 0.13 | ... S41: =S13/R13-1 -> 0.12
B42: Gross Profit Margin % | D42: =D15/D13 -> 0.48803828 | E42: =E15/E13 -> 0.4694334 | F42: =F15/F13 -> 0.42851135 | G42: =G15/G13 -> 0.45196641 | H42: =H15/H13 -> 0.50813219 | I42: =I15/I13 -> 0.50253901 | J42: =J15/J13 -> 0.48 | K42: =K15/K13 -> 0.48 | ... S42: =S15/S13 -> 0.5
B43: EBITDA Margin % | D43: =D25/D13 -> 0.19685578 | E43: =E25/E13 -> 0.19905567 | F43: =F25/F13 -> 0.17672414 | G43: =G25/G13 -> 0.18537485 | H43: =H25/H13 -> 0.20988294 | I43: =I25/I13 -> 0.19748869 | J43: =J25/J13 -> 0.169 | K43: =K25/K13 -> 0.169 | ... S43: =S25/S13 -> 0.189
B44: EBIT Margin % | D44: =D30/D13 -> 0.17771702 | E44: =E30/E13 -> 0.18178429 | F44: =F30/F13 -> 0.16211102 | G44: =G30/G13 -> 0.1695002 | H44: =H30/H13 -> 0.19351497 | I44: =I30/I13 -> 0.18105438 | J44: =J30/J13 -> 0.15351727 | K44: =K30/K13 -> 0.15429216 | ... S44: =S30/S13 -> 0.17900329
B45: Actual Tax Rate % | D45: =D38/D36 -> 0.24090247 | E45: =E38/E36 -> 0.21273802 | F45: =F38/F36 -> 0.21611493 | G45: =G38/G36 -> 0.24153758 | H45: =H38/H36 -> 0.22457408 | I45: =I38/I36 -> 0.21644612 | J45: =J38/J36 -> 0.2512 | K45: =K38/K36 -> 0.2512 | ... S45: =S38/S36 -> 0.2512
B46: Net Income Margin % | D46: =D39/D13 -> 0.14258373 | E46: =E39/E13 -> 0.14898111 | F46: =F39/F13 -> 0.1319386 | G46: =G39/G13 -> 0.13539533 | H46: =H39/H13 -> 0.1555993 | I46: =I39/I13 -> 0.15307912 | J46: =J39/J13 -> 0.12287721 | K46: =K39/K13 -> 0.12324463 | ... S46: =S39/S13 -> 0.14305502
B47: Interest Coverage Ratio | D47: =D30/D34 -> 26 | E47: =E30/E34 -> 43.029412 | F47: =F30/F34 -> 39.538462 | G47: =G30/G34 -> 29.553571 | H47: =H30/H34 -> 25.589041 | I47: =I30/I34 -> 37 | J47: =J30/J34 -> 34.744761 | K47: =K30/K34 -> 32.809669 | ... S47: =S30/S34 -> 60.523377
A49: # | B49: Balance Sheet
B51: Assets
B53: Non Current Assets
B54: Property, Plant & Equipment | D54: ='Balance Sheet'!D8 -> 654 | E54: ='Balance Sheet'!E8 -> 572 | F54: ='Balance Sheet'!F8 -> 600 | G54: ='Balance Sheet'!G8 -> 633 | H54: ='Balance Sheet'!H8 -> 700 | I54: ='Balance Sheet'!I8 -> 710 | J54: =Schedules!J56 -> 780.38694 | K54: =Schedules!K56 -> 862.49563 | L54: =Schedules!L56 -> 956.8621 | M54: =Schedules!M56 -> 1063.8974 | N54: =Schedules!N56 -> 1165.2318 | O54: =Schedules!O56 -> 1280.1345 | P54: =Schedules!P56 -> 1433.5947 | Q54: =Schedules!Q56 -> 1631.374 | ... S54: =Schedules!S56 -> 1905.8294
B55: Capital work-in-progress | D55: ='Balance Sheet'!D9 -> 58 | E55: ='Balance Sheet'!E9 -> 24 | F55: ='Balance Sheet'!F9 -> 39 | G55: ='Balance Sheet'!G9 -> 67 | H55: ='Balance Sheet'!H9 -> 44 | I55: ='Balance Sheet'!I9 -> 40 | J55: =Schedules!J69 -> 40 | K55: =Schedules!K69 -> 40 | L55: =Schedules!L69 -> 40 | M55: =Schedules!M69 -> 40 | N55: =Schedules!N69 -> 40 | O55: =Schedules!O69 -> 40 | P55: =Schedules!P69 -> 40 | Q55: =Schedules!Q69 -> 40 | ... S55: =Schedules!S69 -> 40
B56: Right of use assets | D56: ='Balance Sheet'!D10 -> 146 | E56: ='Balance Sheet'!E10 -> 180 | F56: ='Balance Sheet'!F10 -> 178 | G56: ='Balance Sheet'!G10 -> 175 | H56: ='Balance Sheet'!H10 -> 209 | I56: ='Balance Sheet'!I10 -> 230 | J56: =Schedules!J63 -> 177 | K56: =Schedules!K63 -> 124 | L56: =Schedules!L63 -> 71 | M56: =Schedules!M63 -> 18 | N56: =Schedules!N63 -> 0 | O56: =Schedules!O63 -> 0 | P56: =Schedules!P63 -> 0 | Q56: =Schedules!Q63 -> 0 | ... S56: =Schedules!S63 -> 0
B57: Investment Property | D57: ='Balance Sheet'!D11 -> 17 | E57: ='Balance Sheet'!E11 -> 17 | F57: ='Balance Sheet'!F11 -> 22 | G57: ='Balance Sheet'!G11 -> 16 | H57: ='Balance Sheet'!H11 -> 15 | I57: ='Balance Sheet'!I11 -> 15 | J57: =Schedules!J82 -> 15 | K57: =Schedules!K82 -> 15 | L57: =Schedules!L82 -> 15 | M57: =Schedules!M82 -> 15 | N57: =Schedules!N82 -> 15 | O57: =Schedules!O82 -> 15 | P57: =Schedules!P82 -> 15 | Q57: =Schedules!Q82 -> 15 | ... S57: =Schedules!S82 -> 15
B58: Goodwill | D58: ='Balance Sheet'!D12 -> 538 | E58: ='Balance Sheet'!E12 -> 613 | F58: ='Balance Sheet'!F12 -> 654 | G58: ='Balance Sheet'!G12 -> 862 | H58: ='Balance Sheet'!H12 -> 863 | I58: ='Balance Sheet'!I12 -> 857 | J58: =Schedules!J88 -> 857 | K58: =Schedules!K88 -> 857 | L58: =Schedules!L88 -> 857 | M58: =Schedules!M88 -> 857 | N58: =Schedules!N88 -> 857 | O58: =Schedules!O88 -> 857 | P58: =Schedules!P88 -> 857 | Q58: =Schedules!Q88 -> 857 | ... S58: =Schedules!S88 -> 857
...

Sheet Ratio Analysis
B2: ='Input Sheet'!C5 -> Marico Ltd
B3: Ratio Analysis
H4: Current Case
I8: Explicit Forecast Period | N8: Maturity Period
B9: In INR crores unless started otherwise | D9: ='3 Statement Model'!E9 -> 2021 | E9: ='3 Statement Model'!F9 -> 2022 | F9: ='3 Statement Model'!G9 -> 2023 | G9: ='3 Statement Model'!H9 -> 2024 | H9: ='3 Statement Model'!I9 -> 2025 | I9: =H9+1 -> 2026 | J9: =I9+1 -> 2027 | K9: =J9+1 -> 2028 | L9: =K9+1 -> 2029 | M9: =L9+1 -> 2030 | N9: =M9+1 -> 2031 | O9: =N9+1 -> 2032 | P9: =O9+1 -> 2033 | ... R9: =Q9+1 -> 2035
A11: # | B11: Liquidity Ratio
B13: Current Asset | D13: ='3 Statement Model'!E72 -> 3336 | E13: ='3 Statement Model'!F72 -> 3505 | F13: ='3 Statement Model'!G72 -> 3820 | G13: ='3 Statement Model'!H72 -> 4003 | H13: ='3 Statement Model'!I72 -> 5083 | I13: ='3 Statement Model'!J72 -> 5681.9206 | J13: ='3 Statement Model'!K72 -> 6372.9775 | K13: ='3 Statement Model'!L72 -> 6899.7575 | ... R13: ='3 Statement Model'!S72 -> 12671.755
B14: Current Liabilities | D14: ='3 Statement Model'!E106 -> 2013 | E14: ='3 Statement Model'!F106 -> 2153 | F14: ='3 Statement Model'!G106 -> 2429 | G14: ='3 Statement Model'!H106 -> 2444 | H14: ='3 Statement Model'!I106 -> 2461 | I14: ='3 Statement Model'!J106 -> 2762.8662 | J14: ='3 Statement Model'!K106 -> 3126.596 | K14: ='3 Statement Model'!L106 -> 3290.4578 | ... R14: ='3 Statement Model'!S106 -> 5899.1011
B15: Current Ratio | D15: =D13/D14 -> 1.657228 | E15: =E13/E14 -> 1.627961 | F15: =F13/F14 -> 1.5726636 | G15: =G13/G14 -> 1.6378887 | H15: =H13/H14 -> 2.0654206 | I15: =I13/I14 -> 2.0565312 | J15: =J13/J14 -> 2.0383118 | K15: =K13/K14 -> 2.096899 | ... R15: =R13/R14 -> 2.1480823
B17: Current Asset | D17: ='3 Statement Model'!E72 -> 3336 | E17: ='3 Statement Model'!F72 -> 3505 | F17: ='3 Statement Model'!G72 -> 3820 | G17: ='3 Statement Model'!H72 -> 4003 | H17: ='3 Statement Model'!I72 -> 5083 | I17: ='3 Statement Model'!J72 -> 5681.9206 | J17: ='3 Statement Model'!K72 -> 6372.9775 | K17: ='3 Statement Model'!L72 -> 6899.7575 | ... R17: ='3 Statement Model'!S72 -> 12671.755
B18: Inventory | D18: ='3 Statement Model'!E69 -> 1126 | E18: ='3 Statement Model'!F69 -> 1412 | F18: ='3 Statement Model'!G69 -> 1225 | G18: ='3 Statement Model'!H69 -> 1336 | H18: ='3 Statement Model'!I69 -> 1235 | I18: ='3 Statement Model'!J69 -> 1589.9315 | J18: ='3 Statement Model'!K69 -> 1804.5722 | K18: ='3 Statement Model'!L69 -> 1995.7801 | ... R18: ='3 Statement Model'!S69 -> 3853.6787
B19: Prepaid Expenses | D19: 0 | E19: 0 | F19: 0 | G19: 0 | H19: 0 | I19: 0 | J19: 0 | K19: 0 | L19: 0 | M19: 0 | N19: 0 | O19: 0 | P19: 0 | Q19: 0 | R19: 0
B20: Current Liabilities | D20: ='3 Statement Model'!E106 -> 2013 | E20: ='3 Statement Model'!F106 -> 2153 | F20: ='3 Statement Model'!G106 -> 2429 | G20: ='3 Statement Model'!H106 -> 2444 | H20: ='3 Statement Model'!I106 -> 2461 | I20: ='3 Statement Model'!J106 -> 2762.8662 | J20: ='3 Statement Model'!K106 -> 3126.596 | K20: ='3 Statement Model'!L106 -> 3290.4578 | ... R20: ='3 Statement Model'!S106 -> 5899.1011
B21: Quick Ratio (Acid Test) | D21: =(D17-D18-D19)/D20 -> 1.0978639 | E21: =(E17-E18-E19)/E20 -> 0.97213191 | F21: =(F17-F18-F19)/F20 -> 1.0683409 | G21: =(G17-G18-G19)/G20 -> 1.0912439 | H21: =(H17-H18-H19)/H20 -> 1.563592 | I21: =(I17-I18-I19)/I20 -> 1.4810667 | J21: =(J17-J18-J19)/J20 -> 1.4611435 | K21: =(K17-K18-K19)/K20 -> 1.4903633 | ... R21: =(R17-R18-R19)/R20 -> 1.4948169
B23: Inventory Days | D23: ='3 Statement Model'!E112 -> 56.827162 | E23: ='3 Statement Model'!F112 -> 48.694807 | F23: ='3 Statement Model'!G112 -> 49.288458 | G23: ='3 Statement Model'!H112 -> 48.418367 | H23: ='3 Statement Model'!I112 -> 43.320792 | I23: ='3 Statement Model'!J112 -> 47 | J23: ='3 Statement Model'!K112 -> 47 | K23: ='3 Statement Model'!L112 -> 46 | ... R23: ='3 Statement Model'!S112 -> 40
B24: Debtor Days | D24: ='3 Statement Model'!E111 -> 21.021061 | E24: ='3 Statement Model'!F111 -> 19.953743 | F24: ='3 Statement Model'!G111 -> 31.158081 | G24: ='3 Statement Model'!H111 -> 39.400186 | H24: ='3 Statement Model'!I111 -> 39.428492 | I24: ='3 Statement Model'!J111 -> 45 | J24: ='3 Statement Model'!K111 -> 45 | K24: ='3 Statement Model'!L111 -> 42 | ... R24: ='3 Statement Model'!S111 -> 39
B25: Creditor Days | D25: ='3 Statement Model'!E113 -> 90.266979 | E25: ='3 Statement Model'!F113 -> 83.192605 | F25: ='3 Statement Model'!G113 -> 95.359746 | G25: ='3 Statement Model'!H113 -> 116.58014 | H25: ='3 Statement Model'!I113 -> 99.717892 | I25: ='3 Statement Model'!J113 -> 105 | J25: ='3 Statement Model'!K113 -> 105 | K25: ='3 Statement Model'!L113 -> 105 | ... R25: ='3 Statement Model'!S113 -> 100
B26: Cash Conversion Days | D26: =D23+D24-D25 -> -12.418756 | E26: =E23+E24-E25 -> -14.544056 | F26: =F23+F24-F25 -> -14.913208 | G26: =G23+G24-G25 -> -28.761585 | H26: =H23+H24-H25 -> -16.968607 | I26: =I23+I24-I25 -> -13 | J26: =J23+J24-J25 -> -13 | K26: =K23+K24-K25 -> -17 | ... R26: =R23+R24-R25 -> -21
A28: # | B28: Leverage Ratio / Solvency Ratio
B30: Total Debt | D30: =SUM('3 Statement Model'!E88,'3 Statement Model'!E99) -> 348 | E30: =SUM('3 Statement Model'!F88,'3 Statement Model'!F99) -> 345 | F30: =SUM('3 Statement Model'!G88,'3 Statement Model'!G99) -> 475 | G30: =SUM('3 Statement Model'!H88,'3 Statement Model'!H99) -> 383 | H30: =SUM('3 Statement Model'!I88,'3 Statement Model'!I99) -> 379 | I30: =SUM('3 Statement Model'!J88,'3 Statement Model'!J99) -> 493.8936 | J30: =SUM('3 Statement Model'!K88,'3 Statement Model'!K99) -> 560.56924 | K30: =SUM('3 Statement Model'!L88,'3 Statement Model'!L99) -> 475.08243 | ... R30: =SUM('3 Statement Model'!S88,'3 Statement Model'!S99) -> 879.12044
B31: Total Equity | D31: ='3 Statement Model'!E84 -> 3258 | E31: ='3 Statement Model'!F84 -> 3405 | F31: ='3 Statement Model'!G84 -> 3956 | G31: ='3 Statement Model'!H84 -> 4169 | H31: ='3 Statement Model'!I84 -> 4266 | I31: ='3 Statement Model'!J84 -> 4569.4413 | J31: ='3 Statement Model'!K84 -> 4914.8771 | K31: ='3 Statement Model'!L84 -> 5308.1618 | ... R31: ='3 Statement Model'!S84 -> 9272.4831
B32: Debt to Equity Ratio | D32: =D30/D31 -> 0.106814 | E32: =E30/E31 -> 0.10132159 | F32: =F30/F31 -> 0.12007078 | G32: =G30/G31 -> 0.091868554 | H32: =H30/H31 -> 0.088842007 | I32: =I30/I31 -> 0.10808621 | J32: =J30/J31 -> 0.1140556 | K32: =K30/K31 -> 0.089500367 | ... R32: =R30/R31 -> 0.094809604
B34: Total Debt | D34: =SUM('3 Statement Model'!E88,'3 Statement Model'!E99) -> 348 | E34: =SUM('3 Statement Model'!F88,'3 Statement Model'!F99) -> 345 | F34: =SUM('3 Statement Model'!G88,'3 Statement Model'!G99) -> 475 | G34: =SUM('3 Statement Model'!H88,'3 Statement Model'!H99) -> 383 | H34: =SUM('3 Statement Model'!I88,'3 Statement Model'!I99) -> 379 | I34: =SUM('3 Statement Model'!J88,'3 Statement Model'!J99) -> 493.8936 | J34: =SUM('3 Statement Model'!K88,'3 Statement Model'!K99) -> 560.56924 | K34: =SUM('3 Statement Model'!L88,'3 Statement Model'!L99) -> 475.08243 | ... R34: =SUM('3 Statement Model'!S88,'3 Statement Model'!S99) -> 879.12044
B35: Total Asset | D35: ='3 Statement Model'!E74 -> 5510 | E35: ='3 Statement Model'!F74 -> 5786 | F35: ='3 Statement Model'!G74 -> 6946 | G35: ='3 Statement Model'!H74 -> 7421 | H35: ='3 Statement Model'!I74 -> 8338 | I35: ='3 Statement Model'!J74 -> 8943.3076 | J35: ='3 Statement Model'!K74 -> 9652.4731 | K35: ='3 Statement Model'!L74 -> 10209.62 | ... R35: ='3 Statement Model'!S74 -> 16782.584
B36: Debt to Asset Ratio | D36: =D34/D35 -> 0.063157895 | E36: =E34/E35 -> 0.059626685 | F36: =F34/F35 -> 0.068384682 | G36: =G34/G35 -> 0.051610295 | H36: =H34/H35 -> 0.045454545 | I36: =I34/I35 -> 0.055224937 | J36: =J34/J35 -> 0.058075193 | K36: =K34/K35 -> 0.046532824 | ... R36: =R34/R35 -> 0.052382901
B38: Total Equity | D38: ='3 Statement Model'!E84 -> 3258 | E38: ='3 Statement Model'!F84 -> 3405 | F38: ='3 Statement Model'!G84 -> 3956 | G38: ='3 Statement Model'!H84 -> 4169 | H38: ='3 Statement Model'!I84 -> 4266 | I38: ='3 Statement Model'!J84 -> 4569.4413 | J38: ='3 Statement Model'!K84 -> 4914.8771 | K38: ='3 Statement Model'!L84 -> 5308.1618 | ... R38: ='3 Statement Model'!S84 -> 9272.4831
B39: Total Asset | D39: ='3 Statement Model'!E74 -> 5510 | E39: ='3 Statement Model'!F74 -> 5786 | F39: ='3 Statement Model'!G74 -> 6946 | G39: ='3 Statement Model'!H74 -> 7421 | H39: ='3 Statement Model'!I74 -> 8338 | I39: ='3 Statement Model'!J74 -> 8943.3076 | J39: ='3 Statement Model'!K74 -> 9652.4731 | K39: ='3 Statement Model'!L74 -> 10209.62 | ... R39: ='3 Statement Model'!S74 -> 16782.584
B40: Equity To Asset Ratio | D40: =D38/D39 -> 0.59128857 | E40: =E38/E39 -> 0.58848946 | F40: =F38/F39 -> 0.56953642 | G40: =G38/G39 -> 0.56178413 | H40: =H38/H39 -> 0.51163349 | I40: =I38/I39 -> 0.51093416 | J40: =J38/J39 -> 0.5091832 | K40: =K38/K39 -> 0.51991769 | ... R40: =R38/R39 -> 0.55250628
A42: # | B42: Profitability Ratio
B44: Gross Profit | D44: ='3 Statement Model'!E15 -> 3778 | E44: ='3 Statement Model'!F15 -> 4076 | F44: ='3 Statement Model'!G15 -> 4413 | G44: ='3 Statement Model'!H15 -> 4905 | H44: ='3 Statement Model'!I15 -> 5443 | I44: ='3 Statement Model'!J15 -> 5926.7232 | J44: ='3 Statement Model'!K15 -> 6726.8308 | K44: ='3 Statement Model'!L15 -> 7601.3188 | ... R44: ='3 Statement Model'!S15 -> 17582.409
